Workbook

Sheet Как пользоваться
B2: Калькулятор сайзинга и стоимости
B3: ДЗ 4 «Сайзинг, стоимость и оптимизация» · курс System Design
B5: Что это
B6: Рабочий лист для расчёта нагрузки и стоимости трёх систем из домашнего задания. Все формулы уже введены: вы меняете исходные данные и допущения, а расчёт пересчитывается сам.
B7: Калькулятор не заменяет работу — он снимает арифметику, чтобы вы тратили время на выводы, а не на перемножение чисел. Разбираться, откуда взялась каждая формула, всё равно придётся: в сдаваемой работе формулы нужно привести и пояснить.
B9: Цвета ячеек
B10: СЕРЫЕ — исходные данные из задания. Менять не нужно.
B11: ЖЁЛТЫЕ — ваши допущения. Это главное, что вы делаете руками: подставьте свои значения и будьте готовы их обосновать. Значения по умолчанию — просто разумный ориентир, не истина.
B12: БЕЛЫЕ — расчёт. Формулы, не трогайте.
B13: ЗЕЛЁНЫЕ — ключевые результаты, которые пойдут в работу.
B15: Порядок работы
B16: 1. Откройте лист своей системы.
... B28: «2 заказа на пользователя в неделю» и «1 бронирование в месяц» считаем ОТ MAU, не от DAU. Иначе результаты в группе различаются в десять раз и работы несравнимы. В формулах это уже учтено.

Sheet Цены и константы
A1: Цены и константы
A2: ЦЕНЫ — условные, провайдер-агностик
A3: Инстанс 4 vCPU / 16 ГБ | B3: 120 | C3: $/мес | D3: Базовая «рабочая лошадка». 8 vCPU — вдвое дороже
A4: Отдельный vCPU | B4: 30 | C4: $/мес | D4: Для расчёта нод БД
A5: Объектное хранилище, горячее | B5: 23 | C5: $/ТБ-мес | D5: $0.023 за ГБ
A6: Объектное хранилище, архив | B6: 4 | C6: $/ТБ-мес | D6: $0.004 за ГБ, плюс плата за извлечение
A7: Блочный SSD под базу | B7: 100 | C7: $/ТБ-мес | D7: $0.10 за ГБ — самый дорогой тир
A8: Трафик наружу с серверов | B8: 0.08 | C8: $/ГБ | D8: Ingress (внутрь облака) бесплатен
A9: Трафик через CDN | B9: 0.03 | C9: $/ГБ | D9: На больших объёмах медиа — до $0.02
A10: Множитель managed-сервиса | B10: 2 | C10: × | D10: Премия за то, что базу обслуживает провайдер
A11: ИНЖЕНЕРНЫЕ КОНСТАНТЫ
A12: Запросов в секунду на инстанс | B12: 1000 | C12: RPS | D12: Зависит от профиля: с тяжёлым обращением к БД — в 5–10 раз меньше
A13: Множитель запаса на отказ и деплой | B13: 2 | C13: × | D13: N+1, вторая зона, выкатка новой версии
A14: Накладные расходы в базе | B14: 2 | C14: × | D14: Индексы, журнал транзакций, реплика, бэкапы
A15: Секунд в сутках | B15: 86400 | C15: с | D15: Не менять
A17: Жёлтые ячейки можно менять — весь расчёт на листах систем пересчитается.

Sheet Доставка еды
A1: Доставка еды
A2: 5 млн MAU · 500K DAU · 2 заказа в неделю · пик ×3
A4: 1. ВВОДНЫЕ ИЗ ЗАДАНИЯ — менять не нужно
A5: MAU — уникальных пользователей в месяц | B5: 5000000
A6: DAU — активных в день | B6: 500000
A7: Peak Factor | B7: 3 | C7: × | D7: Обед 12:00–14:00 и вечер 18:00–21:00
A8: Заказов в сутки | B8: =$B$5*2/7 -> 1428571.4 | D8: 2 заказа в неделю от MAU — договорённость группы
A10: 2. ВАШИ ДОПУЩЕНИЯ — заполните и будьте готовы обосновать
A11: В задании дан только объём заказов. Всё остальное — ваша оценка. Значения по умолчанию — ориентир, а не истина: меняйте их, если считаете иначе, но зафиксируйте обоснование в работе.
A12: Запросов при оформлении одного заказа | B12: 8 | D12: Каталог, корзина, адрес, оплата, подтверждение — это не один запрос
A13: Событий статуса на заказ | B13: 40 | D13: Создан, оплачен, принят, готовится, в пути, доставлен…
A14: Минут клиент следит за курьером на карте | B14: 15 | C14: мин
A15: Секунд между обновлениями карты у клиента | B15: 2 | C15: с | D15: Сейчас приложение само опрашивает сервер. Обратите внимание на этот параметр
A16: Курьеров онлайн одновременно, пик | B16: 8000
A17: Курьеров онлайн одновременно, среднее | B17: 5000
A18: Секунд между GPS-точками курьера | B18: 5 | C18: с
A19: Размер GPS-точки в хранилище | B19: 200 | C19: байт | D19: С индексами
A20: Размер записи о заказе | B20: 3 | C20: КБ | D20: Позиции, адрес, статусы, оплата
A21: Средний размер ответа API | B21: 1 | C21: КБ | D21: JSON без картинок
A22: Сколько дней данные лежат в горячем хранилище | B22: 30 | C22: дней | D22: Дальше — в архив
A23: Горизонт хранения | B23: 3 | C23: лет
A25: 3. RPS — запросов в секунду
A26: Запись: GPS-точки курьеров, пик | B26: =$B$16/$B$18 -> 1600 | C26: RPS
A27: Запись: события статуса заказов, пик | B27: =$B$8*$B$13/'Цены и константы'!$B$15*$B$7 -> 1984.127 | C27: RPS
A28: Запись: оформление заказов, пик | B28: =$B$8/'Цены и константы'!$B$15*$B$7 -> 49.603175 | C28: RPS
A29: ИТОГО ЗАПИСЬ, пик | B29: =$B$26+$B$27+$B$28 -> 3633.7302 | C29: RPS
A30: Обращений на один заказ при слежении | B30: =$B$14*60/$B$15 -> 450
A31: Обращений слежения в сутки | B31: =$B$8*$B$30 -> 6.4285714e+08
A32: Чтение: слежение за курьером, пик | B32: =$B$31/'Цены и константы'!$B$15*$B$7 -> 22321.429 | C32: RPS
A33: Прочих запросов в сутки | B33: =$B$8*$B$12 -> 11428571
A34: Чтение: прочий API, пик | B34: =$B$33/'Цены и константы'!$B$15*$B$7 -> 396.8254 | C34: RPS
A35: ИТОГО ЧТЕНИЕ, пик | B35: =$B$32+$B$34 -> 22718.254 | C35: RPS
A36: Доля чтения во всей нагрузке | B36: =$B$35/($B$35+$B$29) -> 0.86210791 | D36: Посмотрите на эту цифру внимательно
A38: 4. ХРАНИЛИЩЕ
A39: Объём GPS-треков в сутки, сырой | B39: =$B$17/$B$18*'Цены и константы'!$B$15*$B$19/1000000000 -> 17.28 | C39: ГБ
A40: Объём заказов и событий в сутки, сырой | B40: =$B$8*$B$20/1000000 -> 4.2857143 | C40: ГБ
A41: Всего в сутки с накладными | B41: =($B$39+$B$40)*'Цены и константы'!$B$14 -> 43.131429 | C41: ГБ | D41: Индексы, реплика, бэкапы
A42: Объём за 1 год | B42: =$B$41*365/1000 -> 15.742971 | C42: ТБ
A43: Объём за горизонт хранения | B43: =$B$41*365*$B$23/1000 -> 47.228914 | C43: ТБ
A44: в т.ч. горячее | B44: =$B$41*$B$22/1000 -> 1.2939429 | C44: ТБ
...

Sheet Платёжный сервис
A1: Платёжный сервис
A2: 10 млн MAU · 1 млн DAU · 5 транзакций в день · пик ×4
A4: 1. ВВОДНЫЕ ИЗ ЗАДАНИЯ — менять не нужно
A5: MAU — уникальных пользователей в месяц | B5: 10000000
A6: DAU — активных в день | B6: 1000000
A7: Peak Factor | B7: 4 | C7: × | D7: Дни зарплат и распродаж
A8: Транзакций в сутки | B8: =$B$6*5 -> 5000000 | D8: 5 транзакций на активного пользователя в день
A10: 2. ВАШИ ДОПУЩЕНИЯ — заполните и будьте готовы обосновать
A11: В задании дан только объём транзакций. Нагрузку на чтение — проверки баланса, история операций — оцениваете вы. Для платёжного сервиса отдельно важны срок хранения и объём аудита: это требование регулятора, а не ваш выбор.
A12: Запросов на одну транзакцию | B12: 6 | D12: Проверка баланса, лимиты, антифрод, проводка, уведомление
A13: Проверок баланса на пользователя в день | B13: 3 | D13: Открыл приложение — увидел баланс
A14: Просмотров истории на пользователя в день | B14: 1
A15: Запросов на один экран чтения | B15: 3 | D15: Fan-out: баланс, лента, курсы
A16: Размер записи о транзакции | B16: 1 | C16: КБ
A17: Множитель аудит-лога | B17: 3 | C17: × | D17: На каждую транзакцию пишется история изменений и события антифрода
A18: Средний размер ответа API | B18: 2 | C18: КБ
A19: Сколько дней данные лежат в горячем хранилище | B19: 90 | C19: дней | D19: Свежая история под рукой, остальное в архив
A20: Горизонт хранения | B20: 5 | C20: лет | D20: Требование регулятора и бухучёта
A22: 3. RPS — запросов в секунду
A23: Запись: транзакции, пик | B23: =$B$8/'Цены и константы'!$B$15*$B$7 -> 231.48148 | C23: RPS
A24: Запись: аудит-лог, пик | B24: =$B$23*$B$17 -> 694.44444 | C24: RPS
A25: ИТОГО ЗАПИСЬ, пик | B25: =$B$23+$B$24 -> 925.92593 | C25: RPS
A26: Запросов на проверку баланса в сутки | B26: =$B$6*$B$13*$B$15 -> 9000000
A27: Запросов на историю в сутки | B27: =$B$6*$B$14*$B$15 -> 3000000
A28: Запросов внутри транзакций в сутки | B28: =$B$8*$B$12 -> 30000000
A29: Всего запросов чтения в сутки | B29: =$B$26+$B$27+$B$28 -> 42000000
A30: ИТОГО ЧТЕНИЕ, пик | B30: =$B$29/'Цены и константы'!$B$15*$B$7 -> 1944.4444 | C30: RPS
A31: Доля чтения во всей нагрузке | B31: =$B$30/($B$30+$B$25) -> 0.67741935
A33: 4. ХРАНИЛИЩЕ
A34: Объём транзакций в сутки, сырой | B34: =$B$8*$B$16/1000000 -> 5 | C34: ГБ
A35: Объём аудит-лога в сутки, сырой | B35: =$B$34*$B$17 -> 15 | C35: ГБ
A36: Всего в сутки с накладными | B36: =($B$34+$B$35)*'Цены и константы'!$B$14 -> 40 | C36: ГБ
A37: Объём за 1 год | B37: =$B$36*365/1000 -> 14.6 | C37: ТБ
A38: Объём за 3 года | B38: =$B$36*365*3/1000 -> 43.8 | C38: ТБ
A39: Объём за горизонт хранения | B39: =$B$36*365*$B$20/1000 -> 73 | C39: ТБ | D39: Данные удалить нельзя — регулятор
A40: в т.ч. горячее | B40: =$B$36*$B$19/1000 -> 3.6 | C40: ТБ
A41: в т.ч. архив | B41: =$B$39-$B$40 -> 69.4 | C41: ТБ
A43: 5. BANDWIDTH — трафик наружу
A44: Трафик в сутки | B44: =($B$29+$B$8)*$B$18/1000000 -> 94 | C44: ГБ
A45: Трафик в месяц | B45: =$B$44*30 -> 2820 | C45: ГБ
...

Sheet Бронирование
A1: Бронирование
A2: 3 млн MAU · 300K DAU · 1 бронирование в месяц · пик ×5
A4: 1. ВВОДНЫЕ ИЗ ЗАДАНИЯ — менять не нужно
A5: MAU — уникальных пользователей в месяц | B5: 3000000
A6: DAU — активных в день | B6: 300000
A7: Peak Factor | B7: 5 | C7: × | D7: Сезон отпусков
A8: Бронирований в сутки | B8: =$B$5/30 -> 100000 | D8: 1 бронирование в месяц от MAU — договорённость группы
A10: 2. ВАШИ ДОПУЩЕНИЯ — заполните и будьте готовы обосновать
A11: Здесь допущения решают всё. Само бронирование — редкое событие, но до него человек долго ищет и сравнивает. Именно поиск и просмотры создают нагрузку, и их объём определяете вы. Если поставить эти параметры в единицу, задача выродится.
A12: Просмотров карточек на одно бронирование | B12: 30 | D12: Человек сравнивает варианты, прежде чем забронировать
A13: Поисковых запросов на одно бронирование | B13: 5 | D13: Поиск по датам, городу, фильтрам
A14: Запросов на один просмотр карточки | B14: 4 | D14: Описание, фото, отзывы, доступность дат
A15: Запросов на один поиск | B15: 2 | D15: Сам поиск и подгрузка следующей страницы
A16: Размер записи о бронировании | B16: 3 | C16: КБ | D16: Гость, даты, объект, оплата, статус
A17: Средний размер ответа API | B17: 3 | C17: КБ | D17: Карточки объектов тяжелее обычного JSON
A18: Сколько дней данные лежат в горячем хранилище | B18: 90 | C18: дней
A19: Горизонт хранения | B19: 3 | C19: лет
A21: 3. RPS — запросов в секунду
A22: Запись: бронирования, пик | B22: =$B$8/'Цены и константы'!$B$15*$B$7 -> 5.787037 | C22: RPS | D22: Обратите внимание, насколько это мало
A23: ИТОГО ЗАПИСЬ, пик | B23: =$B$22 -> 5.787037 | C23: RPS
A24: Запросов на просмотры в сутки | B24: =$B$8*$B$12*$B$14 -> 12000000
A25: Запросов на поиск в сутки | B25: =$B$8*$B$13*$B$15 -> 1000000
A26: Всего запросов чтения в сутки | B26: =$B$24+$B$25 -> 13000000
A27: ИТОГО ЧТЕНИЕ, пик | B27: =$B$26/'Цены и константы'!$B$15*$B$7 -> 752.31481 | C27: RPS
A28: Во сколько раз чтения больше записи | B28: =$B$27/$B$23 -> 130 | C28: × | D28: Классический read-heavy профиль
A30: 4. ХРАНИЛИЩЕ
A31: Объём бронирований в сутки, сырой | B31: =$B$8*$B$16/1000000 -> 0.3 | C31: ГБ
A32: Объём логов поиска и просмотров в сутки | B32: =$B$26*0.2/1000000 -> 2.6 | C32: ГБ | D32: 0.2 КБ на запись лога — тоже допущение, можете изменить
A33: Всего в сутки с накладными | B33: =($B$31+$B$32)*'Цены и константы'!$B$14 -> 5.8 | C33: ГБ
A34: Объём за 1 год | B34: =$B$33*365/1000 -> 2.117 | C34: ТБ
A35: Объём за горизонт хранения | B35: =$B$33*365*$B$19/1000 -> 6.351 | C35: ТБ
A36: в т.ч. горячее | B36: =$B$33*$B$18/1000 -> 0.522 | C36: ТБ
A37: в т.ч. архив | B37: =$B$35-$B$36 -> 5.829 | C37: ТБ
A39: 5. BANDWIDTH — трафик наружу
A40: Трафик в сутки | B40: =$B$26*$B$17/1000000 -> 39 | C40: ГБ
A41: Трафик в месяц | B41: =$B$40*30 -> 1170 | C41: ГБ
A43: 6. РЕСУРСЫ
A44: Инстансов приложения | B44: =ROUNDUP(($B$23+$B$27)/'Цены и константы'!$B$12,0)*'Цены и константы'!$B$13 -> 2 | C44: шт
A45: Нод базы данных | B45: 3 | C45: шт
A46: vCPU на ноду базы | B46: 8 | C46: шт
...
